Workbook

Sheet 2
C2: Using the design chart of CC/DV system based on the calculated peak sensible load per floor area ( 80-90 w/m2) and different values of P (flow rate parameter) below, we find the different parameters (chilled ceiling temperature (°C), supply air temperature (°C), load removal ratio, stratification height (m) and temperature gradient (°C/m)).
C5: room area | F5: A | G5: ='1'!D5 -> 25
C6: the peak total sensible load per floor area (W/m2) | F6: Qs | G6: ='1'!K18 -> 88
C7: chilled ceiling temperature (°C) | F7: Tc | G7: 16
C8: supply air temperature (°C) | F8: Ts | G8: 19
C9: load removal ratio | F9: R | G9: 0.5
C10: stratification height (m) | F10: H | G10: 1.578
C11: temperature gradient (°C/m) | F11: dT/dZ | G11: =I24 -> 1.460825
C12: peak sensible load (w/m2) | F12: Qs | G12: 88
C13: ratio of cooling load to supply mass flow rate P=Qs/m˙s ( kJ/kg) | F13: P | G13: 8
B14: The following equations are used to assess if the proposed system satisfies thermal comfort and indoor air quality requirements.
C21: P | D21: mdot | E21: Tc | F21: Ts | G21: R | H21: H | I21: dT/dZ
C22: 4 | D22: =$G$6/1000*$G$5/C22 -> 0.55 | E22: 17 | F22: 18 | G22: 0.3 | H22: =0.017*E22+0.034*F22-0.036*C22+0.007*$G$6-0.084*G22+0.374 -> 1.7218 | I22: =-0.136*E22-0.008*F22+0.052*C22+0.006*$G$6-0.213*G22+2.946 -> 1.1621
C23: 6 | D23: =$G$6/1000*$G$5/C23 -> 0.36666667 | E23: 17 | F23: 18 | G23: 0.35 | H23: =0.017*E23+0.034*F23-0.036*C23+0.007*$G$6-0.084*G23+0.374 -> 1.6456 | I23: =-0.136*E23-0.008*F23+0.052*C23+0.006*$G$6-0.213*G23+2.946 -> 1.25545
C24: 8 | D24: =$G$6/1000*$G$5/C24 -> 0.275 | E24: 16 | F24: 19 | G24: 0.475 | H24: =0.017*E24+0.034*F24-0.036*C24+0.007*$G$6-0.084*G24+0.374 -> 1.5801 | I24: =-0.136*E24-0.008*F24+0.052*C24+0.006*$G$6-0.213*G24+2.946 -> 1.460825
C25: 10 | D25: =$G$6/1000*$G$5/C25 -> 0.22 | E25: 16 | F25: 19 | G25: 0.525 | H25: =0.017*E25+0.034*F25-0.036*C25+0.007*$G$6-0.084*G25+0.374 -> 1.5039 | I25: =-0.136*E25-0.008*F25+0.052*C25+0.006*$G$6-0.213*G25+2.946 -> 1.554175
C26: 12 | D26: =$G$6/1000*$G$5/C26 -> 0.18333333 | E26: 15.5 | F26: 20.5 | G26: 0.575 | H26: =0.017*E26+0.034*F26-0.036*C26+0.007*$G$6-0.084*G26+0.374 -> 1.4702 | I26: =-0.136*E26-0.008*F26+0.052*C26+0.006*$G$6-0.213*G26+2.946 -> 1.703525
C27: 14 | D27: =$G$6/1000*$G$5/C27 -> 0.15714286 | E27: 15.5 | F27: 20.5 | G27: 0.6 | H27: =0.017*E27+0.034*F27-0.036*C27+0.007*$G$6-0.084*G27+0.374 -> 1.3961 | I27: =-0.136*E27-0.008*F27+0.052*C27+0.006*$G$6-0.213*G27+2.946 -> 1.8022
B31: After satisfying the requirements of comfort ( H> 1m) and indoor air quality (dT/dZ<2.5 oC/m), the energy consumption of the DV and CC system can be found by doing the following:
B33: a. Finding the exhaust air temperature Tr (°C) as follows:
A35: Design | B35: P | C35: mdot | D35: Ts | E35: dT/dZ | F35: Tr
A36: 1 | B36: 4 | C36: =$G$6/1000*$G$5/B36 -> 0.55 | D36: 18 | E36: =I22 -> 1.1621 | F36: =D36+E36*3*3/(4) -> 20.614725
A37: 2 | B37: 6 | C37: =$G$6/1000*$G$5/B37 -> 0.36666667 | D37: 18 | E37: =I23 -> 1.25545 | F37: =D37+E37*3*3/(4) -> 20.824762
A38: 3 | B38: 8 | C38: =$G$6/1000*$G$5/B38 -> 0.275 | D38: 19 | E38: =I24 -> 1.460825 | F38: =D38+E38*3*3/(4) -> 22.286856
A39: 4 | B39: 10 | C39: =$G$6/1000*$G$5/B39 -> 0.22 | D39: 19 | E39: =I25 -> 1.554175 | F39: =D39+E39*3*3/(4) -> 22.496894
A40: 5 | B40: 12 | C40: =$G$6/1000*$G$5/B40 -> 0.18333333 | D40: 20.5 | E40: =I26 -> 1.703525 | F40: =D40+E40*3*3/(4) -> 24.332931
A41: 6 | B41: 14 | C41: =$G$6/1000*$G$5/B41 -> 0.15714286 | D41: 20.5 | E41: =I27 -> 1.8022 | F41: =D41+E41*3*3/(4) -> 24.55495
B43: b- Finding the amount of reheat used from the following energy balance:
M44: =1000 -> 1000
A47: Design | B47: P | C47: mdot | D47: Tc | E47: Ts | F47: R | G47: H | H47: dT/dZ | I47: Qcc | J47: Qsdv | K47: Qrh | L47: Wv | M47: Tdp,min | N47: HR (wa, max) | O47: Tdp | P47: Ws. Max | Q47: m cond | R47: Qc | S47: fan power P (W) | T47: E DV | U47: mw | V47: Tw_out | W47: Ppump | X47: E total
A48: 1 | B48: 4 | C48: =$G$6/1000*$G$5/B48 -> 0.55 | D48: 17 | E48: 18 | F48: 0.3 | G48: =0.017*D48+0.034*E48-0.036*B48+0.007*$G$6-0.084*F48+0.374 -> 1.7218 | H48: =-0.136*D48-0.008*E48+0.052*B48+0.006*$G$6-0.213*F48+2.946 -> 1.1621 | I48: =F48*$G$6*$G$5 -> 660 | J48: =I48*(1/F48-1) -> 1540 | K48: =C48*1000*(E48-Table1[[#This Row],[Tdp]]) -> 5185.4 | L48: =12*'2'!$F$57/'2'!C48 -> 0.00030545455 | M48: =D48-1.5 -> 15.5 | N48: =EXP((17.625*M48)/(243.04+M48))/EXP((17.625*F36)/(243.04+F36))/100 -> 0.0072512241 | O48: 8.572 | P48: =Table1[[#This Row],[HR (wa, max)]]-12*$F$57/C48 -> 0.0069457696 | Q48: =C48*(0.01622-N48)+L48*C48 -> 0.0051008267 | R48: =J48+K48+Q48*2257+C48*1005*(30.7-E48) -> 13756.838 | S48: =C48*1500/(0.5*1) -> 1650 | T48: =S48+0.33*K48+0.5*R48 -> 10239.601 | U48: =I48/(4200*(V48-15)) -> 0.039285714 | V48: =2*D48-15 -> 19 | W48: =U48*9.81*4/0.8 -> 1.9269643 | X48: =Table1[[#This Row],[Ppump]]+Table1[[#This Row],[E DV]] -> 10241.528
A49: 2 | B49: 6 | C49: =$G$6/1000*$G$5/B49 -> 0.36666667 | D49: 17 | E49: 18 | F49: 0.35 | G49: =0.017*D49+0.034*E49-0.036*B49+0.007*$G$6-0.084*F49+0.374 -> 1.6456 | H49: =-0.136*D49-0.008*E49+0.052*B49+0.006*$G$6-0.213*F49+2.946 -> 1.25545 | I49: =F49*$G$6*$G$5 -> 770 | J49: =I49*(1/F49-1) -> 1430 | K49: =C49*1000*(E49-Table1[[#This Row],[Tdp]]) -> 3666.3 | L49: =12*'2'!$F$57/'2'!C49 -> 0.00045818182 | M49: =D49-1.5 -> 15.5 | N49: =EXP((17.625*M49)/(243.04+M49))/EXP((17.625*F37)/(243.04+F37))/100 -> 0.0071580505 | O49: 8.001 | P49: =Table1[[#This Row],[HR (wa, max)]]-12*$F$57/C49 -> 0.0066998687 | Q49: =C49*(0.01622-N49)+L49*C49 -> 0.0034907148 | R49: =J49+K49+Q49*2257+C49*1005*(30.7-E49) -> 9784.1285 | S49: =C49*1500/(0.5*1) -> 1100 | T49: =S49+0.33*K49+0.5*R49 -> 7201.9433 | U49: =I49/(4200*(V49-15)) -> 0.045833333 | V49: =2*D49-15 -> 19 | W49: =U49*9.81*4/0.8 -> 2.248125 | X49: =Table1[[#This Row],[Ppump]]+Table1[[#This Row],[E DV]] -> 7204.1914
A50: 3 | B50: 8 | C50: =$G$6/1000*$G$5/B50 -> 0.275 | D50: 16 | E50: 19 | F50: 0.475 | G50: =0.017*D50+0.034*E50-0.036*B50+0.007*$G$6-0.084*F50+0.374 -> 1.5801 | H50: =-0.136*D50-0.008*E50+0.052*B50+0.006*$G$6-0.213*F50+2.946 -> 1.460825 | I50: =F50*$G$6*$G$5 -> 1045 | J50: =I50*(1/F50-1) -> 1155 | K50: =C50*1000*(E50-Table1[[#This Row],[Tdp]]) -> 3769.975 | L50: =12*'2'!$F$57/'2'!C50 -> 0.00061090909 | M50: =D50-1.5 -> 14.5 | N50: =EXP((17.625*M50)/(243.04+M50))/EXP((17.625*F38)/(243.04+F38))/100 -> 0.0061376781 | O50: 5.291 | P50: =Table1[[#This Row],[HR (wa, max)]]-12*$F$57/C50 -> 0.005526769 | Q50: =C50*(0.01622-N50)+L50*C50 -> 0.0029406385 | R50: =J50+K50+Q50*2257+C50*1005*(30.7-E50) -> 8165.1995 | S50: =C50*1500/(0.5*1) -> 825 | T50: =S50+0.33*K50+0.5*R50 -> 6151.6915 | U50: =I50/(4200*(V50-15)) -> 0.12440476 | V50: =2*D50-15 -> 17 | W50: =U50*9.81*4/0.8 -> 6.1020536 | X50: =Table1[[#This Row],[Ppump]]+Table1[[#This Row],[E DV]] -> 6157.7936
A51: 4 | B51: 10 | C51: =$G$6/1000*$G$5/B51 -> 0.22 | D51: 16 | E51: 19 | F51: 0.525 | G51: =0.017*D51+0.034*E51-0.036*B51+0.007*$G$6-0.084*F51+0.374 -> 1.5039 | H51: =-0.136*D51-0.008*E51+0.052*B51+0.006*$G$6-0.213*F51+2.946 -> 1.554175 | I51: =F51*$G$6*$G$5 -> 1155 | J51: =I51*(1/F51-1) -> 1045 | K51: =C51*1000*(E51-Table1[[#This Row],[Tdp]]) -> 3149.96 | L51: =12*'2'!$F$57/'2'!C51 -> 0.00076363636 | M51: =D51-1.5 -> 14.5 | N51: =EXP((17.625*M51)/(243.04+M51))/EXP((17.625*F39)/(243.04+F39))/100 -> 0.0060597971 | O51: 4.682 | P51: =Table1[[#This Row],[HR (wa, max)]]-12*$F$57/C51 -> 0.0052961607 | Q51: =C51*(0.01622-N51)+L51*C51 -> 0.0024032446 | R51: =J51+K51+Q51*2257+C51*1005*(30.7-E51) -> 6787.2541 | S51: =C51*1500/(0.5*1) -> 660 | T51: =S51+0.33*K51+0.5*R51 -> 5093.1139 | U51: =I51/(4200*(V51-15)) -> 0.1375 | V51: =2*D51-15 -> 17 | W51: =U51*9.81*4/0.8 -> 6.744375 | X51: =Table1[[#This Row],[Ppump]]+Table1[[#This Row],[E DV]] -> 5099.8582
A52: 5 | B52: 12 | C52: =$G$6/1000*$G$5/B52 -> 0.18333333 | D52: 15.5 | E52: 20.5 | F52: 0.575 | G52: =0.017*D52+0.034*E52-0.036*B52+0.007*$G$6-0.084*F52+0.374 -> 1.4702 | H52: =-0.136*D52-0.008*E52+0.052*B52+0.006*$G$6-0.213*F52+2.946 -> 1.703525 | I52: =F52*$G$6*$G$5 -> 1265 | J52: =I52*(1/F52-1) -> 935 | K52: =C52*1000*(E52-Table1[[#This Row],[Tdp]]) -> 3415.3167 | L52: =12*'2'!$F$57/'2'!C52 -> 0.00091636364 | M52: =D52-1.5 -> 14 | N52: =EXP((17.625*M52)/(243.04+M52))/EXP((17.625*F40)/(243.04+F40))/100 -> 0.005251669 | O52: 1.871 | P52: =Table1[[#This Row],[HR (wa, max)]]-12*$F$57/C52 -> 0.0043353054 | Q52: =C52*(0.01622-N52)+L52*C52 -> 0.0021788607 | R52: =J52+K52+Q52*2257+C52*1005*(30.7-E52) -> 6234.5844 | S52: =C52*1500/(0.5*1) -> 550 | T52: =S52+0.33*K52+0.5*R52 -> 4794.3467 | U52: =I52/(4200*(V52-15)) -> 0.30119048 | V52: =2*D52-15 -> 16 | W52: =U52*9.81*4/0.8 -> 14.773393 | X52: =Table1[[#This Row],[Ppump]]+Table1[[#This Row],[E DV]] -> 4809.1201
A53: 6 | B53: 14 | C53: =$G$6/1000*$G$5/B53 -> 0.15714286 | D53: 15.5 | E53: 20.5 | F53: 0.6 | G53: =0.017*D53+0.034*E53-0.036*B53+0.007*$G$6-0.084*F53+0.374 -> 1.3961 | H53: =-0.136*D53-0.008*E53+0.052*B53+0.006*$G$6-0.213*F53+2.946 -> 1.8022 | I53: =F53*$G$6*$G$5 -> 1320 | J53: =I53*(1/F53-1) -> 880 | K53: =C53*1000*(E53-Table1[[#This Row],[Tdp]]) -> 3041.9714 | L53: =12*'2'!$F$57/'2'!C53 -> 0.0010690909 | M53: =D53-1.5 -> 14 | N53: =EXP((17.625*M53)/(243.04+M53))/EXP((17.625*F41)/(243.04+F41))/100 -> 0.005182324 | O53: 1.142 | P53: =Table1[[#This Row],[HR (wa, max)]]-12*$F$57/C53 -> 0.0041132331 | Q53: =C53*(0.01622-N53)+L53*C53 -> 0.0019024919 | R53: =J53+K53+Q53*2257+C53*1005*(30.7-E53) -> 5537.1368 | S53: =C53*1500/(0.5*1) -> 471.42857 | T53: =S53+0.33*K53+0.5*R53 -> 4243.8475 | U53: =I53/(4200*(V53-15)) -> 0.31428571 | V53: =2*D53-15 -> 16 | W53: =U53*9.81*4/0.8 -> 15.415714 | X53: =Table1[[#This Row],[Ppump]]+Table1[[#This Row],[E DV]] -> 4259.2632
B55: c- Finding the new humidity ratio due to the water vapor generated from occupants (Wv (kg water/kg dry air)).
E56: Np at peak load is 12
E57: wp= | F57: 1.4e-05
B59: d- Finding the maximum allowable humidity ratio of air near the ceiling to avoid condensation at the dew point temperature (WR (kg water/kg dry air)).
...

Sheet 1
A1: Energy Conservation Assignment
A3: 1- Find the peak total sensible load per floor area (W/m2) due to equipment and at peak occupancy.
B5: area of room (m2) | D5: 25 | F5: height of room (m) | H5: 3 | J5: load per person (w) | L5: 100 | N5: load due to equipment and lighting (w) | R5: 1000
B7: Hour | C7: 1 | D7: 2 | E7: 3 | F7: 4 | G7: 5 | H7: 6 | I7: 7 | J7: 8 | K7: 9 | L7: 10 | M7: 11 | N7: 12
B8: Number of people | C8: 0 | D8: 0 | E8: 0 | F8: 0 | G8: 0 | H8: 0 | I8: 1 | J8: 4 | K8: 5 | L8: 10 | M8: 10 | N8: 12
B9: load due to people ( w/m2) | C9: =C8*$L$5/$D$5 -> 0 | D9: =D8*$L$5/$D$5 -> 0 | E9: =E8*$L$5/$D$5 -> 0 | F9: =F8*$L$5/$D$5 -> 0 | G9: =G8*$L$5/$D$5 -> 0 | H9: =H8*$L$5/$D$5 -> 0 | I9: =I8*$L$5/$D$5 -> 4 | J9: =J8*$L$5/$D$5 -> 16 | ... N9: =N8*$L$5/$D$5 -> 48
B10: load due to equipment and lighting (w/m2) | C10: =$R$5/$D$5 -> 40 | D10: =$R$5/$D$5 -> 40 | E10: =$R$5/$D$5 -> 40 | F10: =$R$5/$D$5 -> 40 | G10: =$R$5/$D$5 -> 40 | H10: =$R$5/$D$5 -> 40 | I10: =$R$5/$D$5 -> 40 | J10: =$R$5/$D$5 -> 40 | ... N10: =$R$5/$D$5 -> 40
B11: total laod ( w/m2) | C11: =C10+C9 -> 40 | D11: =D10+D9 -> 40 | E11: =E10+E9 -> 40 | F11: =F10+F9 -> 40 | G11: =G10+G9 -> 40 | H11: =H10+H9 -> 40 | I11: =I10+I9 -> 44 | J11: =J10+J9 -> 56 | ... N11: =N10+N9 -> 88
B12: Hour | C12: 13 | D12: 14 | E12: 15 | F12: 16 | G12: 17 | H12: 18 | I12: 19 | J12: 20 | K12: 21 | L12: 22 | M12: 23 | N12: 24
B13: Number of people | C13: 12 | D13: 10 | E13: 10 | F13: 10 | G13: 8 | H13: 7 | I13: 7 | J13: 6 | K13: 4 | L13: 2 | M13: 0 | N13: 0
B14: load due to people ( w/m2) | C14: =C13*$L$5/$D$5 -> 48 | D14: =D13*$L$5/$D$5 -> 40 | E14: =E13*$L$5/$D$5 -> 40 | F14: =F13*$L$5/$D$5 -> 40 | G14: =G13*$L$5/$D$5 -> 32 | H14: =H13*$L$5/$D$5 -> 28 | I14: =I13*$L$5/$D$5 -> 28 | J14: =J13*$L$5/$D$5 -> 24 | ... N14: =N13*$L$5/$D$5 -> 0
B15: load due to equipment and lighting (w/m2) | C15: =$R$5/$D$5 -> 40 | D15: =$R$5/$D$5 -> 40 | E15: =$R$5/$D$5 -> 40 | F15: =$R$5/$D$5 -> 40 | G15: =$R$5/$D$5 -> 40 | H15: =$R$5/$D$5 -> 40 | I15: =$R$5/$D$5 -> 40 | J15: =$R$5/$D$5 -> 40 | ... N15: =$R$5/$D$5 -> 40
B16: total laod ( w/m2) | C16: =C15+C14 -> 88 | D16: =D15+D14 -> 80 | E16: =E15+E14 -> 80 | F16: =F15+F14 -> 80 | G16: =G15+G14 -> 72 | H16: =H15+H14 -> 68 | I16: =I15+I14 -> 68 | J16: =J15+J14 -> 64 | ... N16: =N15+N14 -> 40
B18: based on the calculation above, the peak total sensible load per floor area (W/m2) due to equipment and at peak occupancy is occuring at 12 pm and 1 pm and it is equal to : | K18: =N11 -> 88

Sheet Sheet1
F1: Designs | G1: Tr (degrees Celsius) | H1: Specific Humidity (HR) (Kg of H2O/Kg of air | I1: Relative Humidity (%)
B2: Tr | C2: RH | D2: Etot | F2: 1 | G2: 20.61473 | H2: 0.007251224 | I2: 0.47
A3: Design 3 | B3: 22.286856 | C3: 40 | D3: 6157.7936 | F3: 2 | G3: 20.82476 | H3: 0.007158051 | I3: 0.45
A4: Design 4 | B4: 22.496894 | C4: 38 | D4: 5099.8582 | F4: 3 | G4: 22.28686 | H4: 0.006137678 | I4: 0.4
A5: Design 5 | B5: 24.332931 | C5: 35 | D5: 4809.1201 | F5: 4 | G5: 22.49689 | H5: 0.006059797 | I5: 0.38
A6: Design 6 | B6: 24.55495 | C6: 31 | D6: 4259.2632 | F6: 5 | G6: 24.33293 | H6: 0.005251669 | I6: 0.35
F7: 6 | G7: 24.55495 | H7: 0.005182324 | I7: 0.31
