Workbook

Sheet Design
C2: Using the design chart of CC/DV system based on the calculated peak sensible load per floor area ( 80-90 w/m2) and different values of P (flow rate parameter) below, we find the different parameters (chilled ceiling temperature (°C), supply air temperature (°C), load removal ratio, stratification height (m) and temperature gradient (°C/m)).
C5: room area | F5: A | G5: ='Load Data'!D5 -> 25
C6: the peak total sensible load per floor area (W/m2) | F6: Qs | G6: ='Load Data'!K18 -> 88
C7: chilled ceiling temperature (°C) | F7: Tc | G7: 16
C8: supply air temperature (°C) | F8: Ts | G8: 19
C9: load removal ratio | F9: R | G9: 0.5
C10: stratification height (m) | F10: H | G10: 1.578
C11: temperature gradient (°C/m) | F11: dT/dZ | G11: =I24 -> 1.460825
C12: peak sensible load (w/m2) | F12: Qs | G12: 88
C13: ratio of cooling load to supply mass flow rate P=Qs/m˙s ( kJ/kg) | F13: P | G13: 8
B14: The following equations are used to assess if the proposed system satisfies thermal comfort and indoor air quality requirements.
C21: P | D21: mdot | E21: Tc | F21: Ts | G21: R | H21: H | I21: dT/dZ
C22: 4 | D22: =$G$6/1000*$G$5/C22 -> 0.55 | E22: 17 | F22: 18 | G22: 0.3 | H22: =0.017*E22+0.034*F22-0.036*C22+0.007*$G$6-0.084*G22+0.374 -> 1.7218 | I22: =-0.136*E22-0.008*F22+0.052*C22+0.006*$G$6-0.213*G22+2.946 -> 1.1621
C23: 6 | D23: =$G$6/1000*$G$5/C23 -> 0.36666667 | E23: 17 | F23: 18 | G23: 0.35 | H23: =0.017*E23+0.034*F23-0.036*C23+0.007*$G$6-0.084*G23+0.374 -> 1.6456 | I23: =-0.136*E23-0.008*F23+0.052*C23+0.006*$G$6-0.213*G23+2.946 -> 1.25545
C24: 8 | D24: =$G$6/1000*$G$5/C24 -> 0.275 | E24: 16 | F24: 19 | G24: 0.475 | H24: =0.017*E24+0.034*F24-0.036*C24+0.007*$G$6-0.084*G24+0.374 -> 1.5801 | I24: =-0.136*E24-0.008*F24+0.052*C24+0.006*$G$6-0.213*G24+2.946 -> 1.460825
C25: 10 | D25: =$G$6/1000*$G$5/C25 -> 0.22 | E25: 16 | F25: 19 | G25: 0.525 | H25: =0.017*E25+0.034*F25-0.036*C25+0.007*$G$6-0.084*G25+0.374 -> 1.5039 | I25: =-0.136*E25-0.008*F25+0.052*C25+0.006*$G$6-0.213*G25+2.946 -> 1.554175
C26: 12 | D26: =$G$6/1000*$G$5/C26 -> 0.18333333 | E26: 15.5 | F26: 20.5 | G26: 0.575 | H26: =0.017*E26+0.034*F26-0.036*C26+0.007*$G$6-0.084*G26+0.374 -> 1.4702 | I26: =-0.136*E26-0.008*F26+0.052*C26+0.006*$G$6-0.213*G26+2.946 -> 1.703525
C27: 14 | D27: =$G$6/1000*$G$5/C27 -> 0.15714286 | E27: 15.5 | F27: 20.5 | G27: 0.6 | H27: =0.017*E27+0.034*F27-0.036*C27+0.007*$G$6-0.084*G27+0.374 -> 1.3961 | I27: =-0.136*E27-0.008*F27+0.052*C27+0.006*$G$6-0.213*G27+2.946 -> 1.8022
B31: After satisfying the requirements of comfort ( H> 1m) and indoor air quality (dT/dZ<2.5 oC/m), the energy consumption of the DV and CC system can be found by doing the following:
B33: a. Finding the exhaust air temperature Tr (°C) as follows:
A35: Design | B35: P | C35: mdot | D35: Ts | E35: dT/dZ | F35: Tr
A36: 1 | B36: 4 | C36: =$G$6/1000*$G$5/B36 -> 0.55 | D36: 18 | E36: =I22 -> 1.1621 | F36: =D36+E36*3*3/(4) -> 20.614725
A37: 2 | B37: 6 | C37: =$G$6/1000*$G$5/B37 -> 0.36666667 | D37: 18 | E37: =I23 -> 1.25545 | F37: =D37+E37*3*3/(4) -> 20.824762
A38: 3 | B38: 8 | C38: =$G$6/1000*$G$5/B38 -> 0.275 | D38: 19 | E38: =I24 -> 1.460825 | F38: =D38+E38*3*3/(4) -> 22.286856
A39: 4 | B39: 10 | C39: =$G$6/1000*$G$5/B39 -> 0.22 | D39: 19 | E39: =I25 -> 1.554175 | F39: =D39+E39*3*3/(4) -> 22.496894
A40: 5 | B40: 12 | C40: =$G$6/1000*$G$5/B40 -> 0.18333333 | D40: 20.5 | E40: =I26 -> 1.703525 | F40: =D40+E40*3*3/(4) -> 24.332931
A41: 6 | B41: 14 | C41: =$G$6/1000*$G$5/B41 -> 0.15714286 | D41: 20.5 | E41: =I27 -> 1.8022 | F41: =D41+E41*3*3/(4) -> 24.55495
B43: b- Finding the amount of reheat used from the following energy balance:
M44: =1000 -> 1000
A47: Design | B47: P | C47: mdot | D47: Tc | E47: Ts | F47: R | G47: H | H47: dT/dZ | I47: Qcc | J47: Qsdv | K47: Qrh | L47: Wv | M47: Tdp,min | N47: HR (wa, max) | O47: Tdp | P47: Ws. Max | Q47: m cond | R47: Qc | S47: fan power P (W) | T47: E DV | U47: mw | V47: Tw_out | W47: Ppump | X47: E total
A48: 1 | B48: 4 | C48: =$G$6/1000*$G$5/B48 -> 0.55 | D48: 17 | E48: 18 | F48: 0.3 | G48: =0.017*D48+0.034*E48-0.036*B48+0.007*$G$6-0.084*F48+0.374 -> 1.7218 | H48: =-0.136*D48-0.008*E48+0.052*B48+0.006*$G$6-0.213*F48+2.946 -> 1.1621 | I48: =F48*$G$6*$G$5 -> 660 | J48: =I48*(1/F48-1) -> 1540 | K48: =C48*1000*(E48-Table1[[#This Row],[Tdp]]) -> 5185.4 | L48: =12*Design!$F$57/Design!C48 -> 0.00030545455 | M48: =D48-1.5 -> 15.5 | N48: =EXP((17.625*M48)/(243.04+M48))/EXP((17.625*F36)/(243.04+F36))/100 -> 0.0072512241 | O48: 8.572 | P48: =Table1[[#This Row],[HR (wa, max)]]-12*$F$57/C48 -> 0.0069457696 | Q48: =C48*(0.01622-N48)+L48*C48 -> 0.0051008267 | R48: =J48+K48+Q48*2257+C48*1005*(30.7-E48) -> 13756.838 | S48: =C48*1500/(0.5*1) -> 1650 | T48: =S48+0.33*K48+0.5*R48 -> 10239.601 | U48: =I48/(4200*(V48-15)) -> 0.039285714 | V48: =2*D48-15 -> 19 | W48: =U48*9.81*4/0.8 -> 1.9269643 | X48: =Table1[[#This Row],[Ppump]]+Table1[[#This Row],[E DV]] -> 10241.528
A49: 2 | B49: 6 | C49: =$G$6/1000*$G$5/B49 -> 0.36666667 | D49: 17 | E49: 18 | F49: 0.35 | G49: =0.017*D49+0.034*E49-0.036*B49+0.007*$G$6-0.084*F49+0.374 -> 1.6456 | H49: =-0.136*D49-0.008*E49+0.052*B49+0.006*$G$6-0.213*F49+2.946 -> 1.25545 | I49: =F49*$G$6*$G$5 -> 770 | J49: =I49*(1/F49-1) -> 1430 | K49: =C49*1000*(E49-Table1[[#This Row],[Tdp]]) -> 3666.3 | L49: =12*Design!$F$57/Design!C49 -> 0.00045818182 | M49: =D49-1.5 -> 15.5 | N49: =EXP((17.625*M49)/(243.04+M49))/EXP((17.625*F37)/(243.04+F37))/100 -> 0.0071580505 | O49: 8.001 | P49: =Table1[[#This Row],[HR (wa, max)]]-12*$F$57/C49 -> 0.0066998687 | Q49: =C49*(0.01622-N49)+L49*C49 -> 0.0034907148 | R49: =J49+K49+Q49*2257+C49*1005*(30.7-E49) -> 9784.1285 | S49: =C49*1500/(0.5*1) -> 1100 | T49: =S49+0.33*K49+0.5*R49 -> 7201.9433 | U49: =I49/(4200*(V49-15)) -> 0.045833333 | V49: =2*D49-15 -> 19 | W49: =U49*9.81*4/0.8 -> 2.248125 | X49: =Table1[[#This Row],[Ppump]]+Table1[[#This Row],[E DV]] -> 7204.1914
A50: 3 | B50: 8 | C50: =$G$6/1000*$G$5/B50 -> 0.275 | D50: 16 | E50: 19 | F50: 0.475 | G50: =0.017*D50+0.034*E50-0.036*B50+0.007*$G$6-0.084*F50+0.374 -> 1.5801 | H50: =-0.136*D50-0.008*E50+0.052*B50+0.006*$G$6-0.213*F50+2.946 -> 1.460825 | I50: =F50*$G$6*$G$5 -> 1045 | J50: =I50*(1/F50-1) -> 1155 | K50: =C50*1000*(E50-Table1[[#This Row],[Tdp]]) -> 3769.975 | L50: =12*Design!$F$57/Design!C50 -> 0.00061090909 | M50: =D50-1.5 -> 14.5 | N50: =EXP((17.625*M50)/(243.04+M50))/EXP((17.625*F38)/(243.04+F38))/100 -> 0.0061376781 | O50: 5.291 | P50: =Table1[[#This Row],[HR (wa, max)]]-12*$F$57/C50 -> 0.005526769 | Q50: =C50*(0.01622-N50)+L50*C50 -> 0.0029406385 | R50: =J50+K50+Q50*2257+C50*1005*(30.7-E50) -> 8165.1995 | S50: =C50*1500/(0.5*1) -> 825 | T50: =S50+0.33*K50+0.5*R50 -> 6151.6915 | U50: =I50/(4200*(V50-15)) -> 0.12440476 | V50: =2*D50-15 -> 17 | W50: =U50*9.81*4/0.8 -> 6.1020536 | X50: =Table1[[#This Row],[Ppump]]+Table1[[#This Row],[E DV]] -> 6157.7936
A51: 4 | B51: 10 | C51: =$G$6/1000*$G$5/B51 -> 0.22 | D51: 16 | E51: 19 | F51: 0.525 | G51: =0.017*D51+0.034*E51-0.036*B51+0.007*$G$6-0.084*F51+0.374 -> 1.5039 | H51: =-0.136*D51-0.008*E51+0.052*B51+0.006*$G$6-0.213*F51+2.946 -> 1.554175 | I51: =F51*$G$6*$G$5 -> 1155 | J51: =I51*(1/F51-1) -> 1045 | K51: =C51*1000*(E51-Table1[[#This Row],[Tdp]]) -> 3149.96 | L51: =12*Design!$F$57/Design!C51 -> 0.00076363636 | M51: =D51-1.5 -> 14.5 | N51: =EXP((17.625*M51)/(243.04+M51))/EXP((17.625*F39)/(243.04+F39))/100 -> 0.0060597971 | O51: 4.682 | P51: =Table1[[#This Row],[HR (wa, max)]]-12*$F$57/C51 -> 0.0052961607 | Q51: =C51*(0.01622-N51)+L51*C51 -> 0.0024032446 | R51: =J51+K51+Q51*2257+C51*1005*(30.7-E51) -> 6787.2541 | S51: =C51*1500/(0.5*1) -> 660 | T51: =S51+0.33*K51+0.5*R51 -> 5093.1139 | U51: =I51/(4200*(V51-15)) -> 0.1375 | V51: =2*D51-15 -> 17 | W51: =U51*9.81*4/0.8 -> 6.744375 | X51: =Table1[[#This Row],[Ppump]]+Table1[[#This Row],[E DV]] -> 5099.8582
A52: 5 | B52: 12 | C52: =$G$6/1000*$G$5/B52 -> 0.18333333 | D52: 15.5 | E52: 20.5 | F52: 0.575 | G52: =0.017*D52+0.034*E52-0.036*B52+0.007*$G$6-0.084*F52+0.374 -> 1.4702 | H52: =-0.136*D52-0.008*E52+0.052*B52+0.006*$G$6-0.213*F52+2.946 -> 1.703525 | I52: =F52*$G$6*$G$5 -> 1265 | J52: =I52*(1/F52-1) -> 935 | K52: =C52*1000*(E52-Table1[[#This Row],[Tdp]]) -> 3415.3167 | L52: =12*Design!$F$57/Design!C52 -> 0.00091636364 | M52: =D52-1.5 -> 14 | N52: =EXP((17.625*M52)/(243.04+M52))/EXP((17.625*F40)/(243.04+F40))/100 -> 0.005251669 | O52: 1.871 | P52: =Table1[[#This Row],[HR (wa, max)]]-12*$F$57/C52 -> 0.0043353054 | Q52: =C52*(0.01622-N52)+L52*C52 -> 0.0021788607 | R52: =J52+K52+Q52*2257+C52*1005*(30.7-E52) -> 6234.5844 | S52: =C52*1500/(0.5*1) -> 550 | T52: =S52+0.33*K52+0.5*R52 -> 4794.3467 | U52: =I52/(4200*(V52-15)) -> 0.30119048 | V52: =2*D52-15 -> 16 | W52: =U52*9.81*4/0.8 -> 14.773393 | X52: =Table1[[#This Row],[Ppump]]+Table1[[#This Row],[E DV]] -> 4809.1201
A53: 6 | B53: 14 | C53: =$G$6/1000*$G$5/B53 -> 0.15714286 | D53: 15.5 | E53: 20.5 | F53: 0.6 | G53: =0.017*D53+0.034*E53-0.036*B53+0.007*$G$6-0.084*F53+0.374 -> 1.3961 | H53: =-0.136*D53-0.008*E53+0.052*B53+0.006*$G$6-0.213*F53+2.946 -> 1.8022 | I53: =F53*$G$6*$G$5 -> 1320 | J53: =I53*(1/F53-1) -> 880 | K53: =C53*1000*(E53-Table1[[#This Row],[Tdp]]) -> 3041.9714 | L53: =12*Design!$F$57/Design!C53 -> 0.0010690909 | M53: =D53-1.5 -> 14 | N53: =EXP((17.625*M53)/(243.04+M53))/EXP((17.625*F41)/(243.04+F41))/100 -> 0.005182324 | O53: 1.142 | P53: =Table1[[#This Row],[HR (wa, max)]]-12*$F$57/C53 -> 0.0041132331 | Q53: =C53*(0.01622-N53)+L53*C53 -> 0.0019024919 | R53: =J53+K53+Q53*2257+C53*1005*(30.7-E53) -> 5537.1368 | S53: =C53*1500/(0.5*1) -> 471.42857 | T53: =S53+0.33*K53+0.5*R53 -> 4243.8475 | U53: =I53/(4200*(V53-15)) -> 0.31428571 | V53: =2*D53-15 -> 16 | W53: =U53*9.81*4/0.8 -> 15.415714 | X53: =Table1[[#This Row],[Ppump]]+Table1[[#This Row],[E DV]] -> 4259.2632
B55: c- Finding the new humidity ratio due to the water vapor generated from occupants (Wv (kg water/kg dry air)).
E56: Np at peak load is 12
E57: wp= | F57: 1.4e-05
B59: d- Finding the maximum allowable humidity ratio of air near the ceiling to avoid condensation at the dew point temperature (WR (kg water/kg dry air)).
...

Sheet Load Data
A1: Energy Conservation Assignment
A3: 1- Find the peak total sensible load per floor area (W/m2) due to equipment and at peak occupancy.
B5: area of room (m2) | D5: 25 | F5: height of room (m) | H5: 3 | J5: load per person (w) | L5: 100 | N5: load due to equipment and lighting (w) | R5: 1000
B7: Hour | C7: 1 | D7: 2 | E7: 3 | F7: 4 | G7: 5 | H7: 6 | I7: 7 | J7: 8 | K7: 9 | L7: 10 | M7: 11 | N7: 12
B8: Number of people | C8: 0 | D8: 0 | E8: 0 | F8: 0 | G8: 0 | H8: 0 | I8: 1 | J8: 4 | K8: 5 | L8: 10 | M8: 10 | N8: 12
B9: load due to people ( w/m2) | C9: =C8*$L$5/$D$5 -> 0 | D9: =D8*$L$5/$D$5 -> 0 | E9: =E8*$L$5/$D$5 -> 0 | F9: =F8*$L$5/$D$5 -> 0 | G9: =G8*$L$5/$D$5 -> 0 | H9: =H8*$L$5/$D$5 -> 0 | I9: =I8*$L$5/$D$5 -> 4 | J9: =J8*$L$5/$D$5 -> 16 | ... N9: =N8*$L$5/$D$5 -> 48
B10: load due to equipment and lighting (w/m2) | C10: =$R$5/$D$5 -> 40 | D10: =$R$5/$D$5 -> 40 | E10: =$R$5/$D$5 -> 40 | F10: =$R$5/$D$5 -> 40 | G10: =$R$5/$D$5 -> 40 | H10: =$R$5/$D$5 -> 40 | I10: =$R$5/$D$5 -> 40 | J10: =$R$5/$D$5 -> 40 | ... N10: =$R$5/$D$5 -> 40
B11: total laod ( w/m2) | C11: =C10+C9 -> 40 | D11: =D10+D9 -> 40 | E11: =E10+E9 -> 40 | F11: =F10+F9 -> 40 | G11: =G10+G9 -> 40 | H11: =H10+H9 -> 40 | I11: =I10+I9 -> 44 | J11: =J10+J9 -> 56 | ... N11: =N10+N9 -> 88
B12: Hour | C12: 13 | D12: 14 | E12: 15 | F12: 16 | G12: 17 | H12: 18 | I12: 19 | J12: 20 | K12: 21 | L12: 22 | M12: 23 | N12: 24
B13: Number of people | C13: 12 | D13: 10 | E13: 10 | F13: 10 | G13: 8 | H13: 7 | I13: 7 | J13: 6 | K13: 4 | L13: 2 | M13: 0 | N13: 0
B14: load due to people ( w/m2) | C14: =C13*$L$5/$D$5 -> 48 | D14: =D13*$L$5/$D$5 -> 40 | E14: =E13*$L$5/$D$5 -> 40 | F14: =F13*$L$5/$D$5 -> 40 | G14: =G13*$L$5/$D$5 -> 32 | H14: =H13*$L$5/$D$5 -> 28 | I14: =I13*$L$5/$D$5 -> 28 | J14: =J13*$L$5/$D$5 -> 24 | ... N14: =N13*$L$5/$D$5 -> 0
B15: load due to equipment and lighting (w/m2) | C15: =$R$5/$D$5 -> 40 | D15: =$R$5/$D$5 -> 40 | E15: =$R$5/$D$5 -> 40 | F15: =$R$5/$D$5 -> 40 | G15: =$R$5/$D$5 -> 40 | H15: =$R$5/$D$5 -> 40 | I15: =$R$5/$D$5 -> 40 | J15: =$R$5/$D$5 -> 40 | ... N15: =$R$5/$D$5 -> 40
B16: total laod ( w/m2) | C16: =C15+C14 -> 88 | D16: =D15+D14 -> 80 | E16: =E15+E14 -> 80 | F16: =F15+F14 -> 80 | G16: =G15+G14 -> 72 | H16: =H15+H14 -> 68 | I16: =I15+I14 -> 68 | J16: =J15+J14 -> 64 | ... N16: =N15+N14 -> 40
B18: based on the calculation above, the peak total sensible load per floor area (W/m2) due to equipment and at peak occupancy is occuring at 12 pm and 1 pm and it is equal to : | K18: =N11 -> 88

Sheet Economic Analysis
A1: Column1 | B1: Investment | C1: Installation | D1: Energy | E1: Annual Mantinance | F1: Salvage Value | G1: Previous Energy | H1: liter of diesel | L1: System | M1: Initial Investment | N1: Installation Cost | O1: Annual Energy Cost | P1: Salvage Value | Q1: Annual Maintenance Costs
A2: CCDV | B2: 1900 | C2: 200 | D2: 840 | E2: 10 | F2: 54 | G2: 2000 | H2: =Table8[[#This Row],[Energy]]*0.4 -> 336 | L2: CC-DV | M2: 1000$+900$ | N2: 100$+100$ | O2: 0.84 MWh | P2: 54$ | Q2: 10$
A3: Mixed-Mode | B3: 1080 | C3: 54 | D3: 1500 | E3: 10.8 | F3: 50 | G3: 2000 | H3: =Table8[[#This Row],[Energy]]*0.4 -> 600 | L3: Mixed Mode | M3: 1080$ | N3: 54$ | O3: 1.5 MWh | P3: 50$ | Q3: 10.8$
A9: rate of electricity price increase | B9: =2% -> 0.02
A10: i | B10: 0.0475
A11: f | B11: =3.8% -> 0.038
A12: r | B12: =(1+B10)/(1+B11)-1 -> 0.0091522158
A14: Costs without interest rate:($)
A15: System | B15: 0 | C15: 1 | D15: 2 | E15: 3 | F15: 4 | G15: 5 | H15: 6 | I15: 7 | J15: 8 | K15: 9 | L15: 10 | M15: 11 | N15: 12 | O15: 13 | P15: 14 | Q15: 15 | R15: 16 | S15: 17 | T15: 18 | U15: 19 | V15: 20
A16: CCDV | B16: =-B2-C2 -> -2100 | C16: =0.168*($G2-$D2)*(1+$B$9)^(Table6[[#Headers],[1]]-1)-$E2 -> 184.88 | D16: =0.168*($G2-$D2)*(1+$B$9)^(Table6[[#Headers],[2]]-1)-$E2 -> 188.7776 | E16: =0.168*($G2-$D2)*(1+$B$9)^(Table6[[#Headers],[3]]-1)-$E2 -> 192.75315 | F16: =0.168*($G2-$D2)*(1+$B$9)^(Table6[[#Headers],[4]]-1)-$E2 -> 196.80822 | G16: =0.168*($G2-$D2)*(1+$B$9)^(Table6[[#Headers],[5]]-1)-$E2 -> 200.94438 | H16: =0.168*($G2-$D2)*(1+$B$9)^(Table6[[#Headers],[6]]-1)-$E2 -> 205.16327 | I16: =0.168*($G2-$D2)*(1+$B$9)^(Table6[[#Headers],[7]]-1)-$E2 -> 209.46653 | J16: =0.168*($G2-$D2)*(1+$B$9)^(Table6[[#Headers],[8]]-1)-$E2 -> 213.85586 | K16: =0.168*($G2-$D2)*(1+$B$9)^(Table6[[#Headers],[9]]-1)-$E2 -> 218.33298 | L16: =0.168*($G2-$D2)*(1+$B$9)^(Table6[[#Headers],[10]]-1)-$E2 -> 222.89964 | M16: =0.168*($G2-$D2)*(1+$B$9)^(Table6[[#Headers],[11]]-1)-$E2 -> 227.55763 | N16: =0.168*($G2-$D2)*(1+$B$9)^(Table6[[#Headers],[12]]-1)-$E2 -> 232.30879 | O16: =0.168*($G2-$D2)*(1+$B$9)^(Table6[[#Headers],[13]]-1)-$E2 -> 237.15496 | P16: =0.168*($G2-$D2)*(1+$B$9)^(Table6[[#Headers],[14]]-1)-$E2 -> 242.09806 | Q16: =0.168*($G2-$D2)*(1+$B$9)^(Table6[[#Headers],[15]]-1)-$E2 -> 247.14002 | R16: =0.168*($G2-$D2)*(1+$B$9)^(Table6[[#Headers],[16]]-1)-$E2 -> 252.28282 | S16: =0.168*($G2-$D2)*(1+$B$9)^(Table6[[#Headers],[17]]-1)-$E2 -> 257.52848 | T16: =0.168*($G2-$D2)*(1+$B$9)^(Table6[[#Headers],[18]]-1)-$E2 -> 262.87905 | U16: =0.168*($G2-$D2)*(1+$B$9)^(Table6[[#Headers],[19]]-1)-$E2 -> 268.33663 | V16: =0.168*($G2-$D2)*(1+$B$9)^(Table6[[#Headers],[20]]-1)-$E2+F2 -> 327.90336
A17: Mixed Mode | B17: =-B3-C3 -> -1134 | C17: =0.168*($G3-$D3)*(1+$B$9)^(Table6[[#Headers],[1]]-1)-$E3 -> 73.2 | D17: =0.168*($G3-$D3)*(1+$B$9)^(Table6[[#Headers],[2]]-1)-$E3 -> 74.88 | E17: =0.168*($G3-$D3)*(1+$B$9)^(Table6[[#Headers],[3]]-1)-$E3 -> 76.5936 | F17: =0.168*($G3-$D3)*(1+$B$9)^(Table6[[#Headers],[4]]-1)-$E3 -> 78.341472 | G17: =0.168*($G3-$D3)*(1+$B$9)^(Table6[[#Headers],[5]]-1)-$E3 -> 80.124301 | H17: =0.168*($G3-$D3)*(1+$B$9)^(Table6[[#Headers],[6]]-1)-$E3 -> 81.942787 | I17: =0.168*($G3-$D3)*(1+$B$9)^(Table6[[#Headers],[7]]-1)-$E3 -> 83.797643 | J17: =0.168*($G3-$D3)*(1+$B$9)^(Table6[[#Headers],[8]]-1)-$E3 -> 85.689596 | K17: =0.168*($G3-$D3)*(1+$B$9)^(Table6[[#Headers],[9]]-1)-$E3 -> 87.619388 | L17: =0.168*($G3-$D3)*(1+$B$9)^(Table6[[#Headers],[10]]-1)-$E3 -> 89.587776 | M17: =0.168*($G3-$D3)*(1+$B$9)^(Table6[[#Headers],[11]]-1)-$E3 -> 91.595531 | N17: =0.168*($G3-$D3)*(1+$B$9)^(Table6[[#Headers],[12]]-1)-$E3 -> 93.643442 | O17: =0.168*($G3-$D3)*(1+$B$9)^(Table6[[#Headers],[13]]-1)-$E3 -> 95.732311 | P17: =0.168*($G3-$D3)*(1+$B$9)^(Table6[[#Headers],[14]]-1)-$E3 -> 97.862957 | Q17: =0.168*($G3-$D3)*(1+$B$9)^(Table6[[#Headers],[15]]-1)-$E3 -> 100.03622 | R17: =0.168*($G3-$D3)*(1+$B$9)^(Table6[[#Headers],[16]]-1)-$E3 -> 102.25294 | S17: =0.168*($G3-$D3)*(1+$B$9)^(Table6[[#Headers],[17]]-1)-$E3 -> 104.514 | T17: =0.168*($G3-$D3)*(1+$B$9)^(Table6[[#Headers],[18]]-1)-$E3 -> 106.82028 | U17: =0.168*($G3-$D3)*(1+$B$9)^(Table6[[#Headers],[19]]-1)-$E3 -> 109.17268 | V17: =0.168*($G3-$D3)*(1+$B$9)^(Table6[[#Headers],[20]]-1)-$E3+F3 -> 161.57214
A21: Costs with intest rate:($)
A22: System | B22: 0 | C22: 1 | D22: 2 | E22: 3 | F22: 4 | G22: 5 | H22: 6 | I22: 7 | J22: 8 | K22: 9 | L22: 10 | M22: 11 | N22: 12 | O22: 13 | P22: 14 | Q22: 15 | R22: 16 | S22: 17 | T22: 18 | U22: 19 | V22: 20
A23: CCDV | B23: =B16*(1+$B111)^(B22) -> -2100 | C23: =C16/((1+$B12)^(C22)) -> 183.20328 | D23: =D16/((1+$B12)^(D22)) -> 185.369 | E23: =E16/((1+$B12)^(E22)) -> 187.55621 | F23: =F16/((1+$B12)^(F22)) -> 189.76517 | G23: =G16/((1+$B12)^(G22)) -> 191.99613 | H23: =H16/((1+$B12)^(H22)) -> 194.24933 | I23: =I16/((1+$B12)^(I22)) -> 196.52504 | J23: =J16/((1+$B12)^(J22)) -> 198.82351 | ... V23: =V16/((1+$B12)^(V22)) -> 273.2828
A24: Mixed Mode | B24: =B17*(1+$B112)^(B23) -> -1134 | C24: =C17/((1+$B12)^(C22)) -> 72.536134 | D24: =D17/((1+$B12)^(D22)) -> 73.527954 | E24: =E17/((1+$B12)^(E22)) -> 74.528512 | F24: =F17/((1+$B12)^(F22)) -> 75.537919 | G24: =G17/((1+$B12)^(G22)) -> 76.556288 | H24: =H17/((1+$B12)^(H22)) -> 77.583732 | I24: =I17/((1+$B12)^(I22)) -> 78.620365 | J24: =J17/((1+$B12)^(J22)) -> 79.666304 | ... V24: =V17/((1+$B12)^(V22)) -> 134.65823
A27: System | B27: NPV($) | C27: IRR | D27: CER
A28: CCDV | B28: =SUM(B23:V23) -> 2046.3034 | C28: =IRR(B16:V16) -> 0.081522538 | D28: =B28/-B16 -> 0.97443017
A29: Mixed Mode | B29: =SUM(B24:V24) -> 557.35713 | C29: =IRR(B17:V17) -> 0.048305007 | D29: =B29/-B17 -> 0.49149658
A34: Benefits without interest rate: ($)
A35: System | B35: 0 | C35: 1 | D35: 2 | E35: 3 | F35: 4 | G35: 5 | H35: 6 | I35: 7 | J35: 8 | K35: 9 | L35: 10 | M35: 11 | N35: 12 | O35: 13 | P35: 14 | Q35: 15 | R35: 16 | S35: 17 | T35: 18 | U35: 19 | V35: 20
A36: CCDV | B36: 0 | C36: =0.168*($G2)*(1+$B$9)^(Table6[[#Headers],[1]]-1) -> 336 | D36: =0.168*($G2)*(1+$B$9)^(Table6[[#Headers],[2]]-1) -> 342.72 | E36: =0.168*($G2)*(1+$B$9)^(Table6[[#Headers],[3]]-1) -> 349.5744 | F36: =0.168*($G2)*(1+$B$9)^(Table6[[#Headers],[4]]-1) -> 356.56589 | G36: =0.168*($G2)*(1+$B$9)^(Table6[[#Headers],[5]]-1) -> 363.69721 | H36: =0.168*($G2)*(1+$B$9)^(Table6[[#Headers],[6]]-1) -> 370.97115 | I36: =0.168*($G2)*(1+$B$9)^(Table6[[#Headers],[7]]-1) -> 378.39057 | J36: =0.168*($G2)*(1+$B$9)^(Table6[[#Headers],[8]]-1) -> 385.95838 | K36: =0.168*($G2)*(1+$B$9)^(Table6[[#Headers],[9]]-1) -> 393.67755 | L36: =0.168*($G2)*(1+$B$9)^(Table6[[#Headers],[10]]-1) -> 401.5511 | M36: =0.168*($G2)*(1+$B$9)^(Table6[[#Headers],[11]]-1) -> 409.58213 | N36: =0.168*($G2)*(1+$B$9)^(Table6[[#Headers],[12]]-1) -> 417.77377 | O36: =0.168*($G2)*(1+$B$9)^(Table6[[#Headers],[13]]-1) -> 426.12924 | P36: =0.168*($G2)*(1+$B$9)^(Table6[[#Headers],[14]]-1) -> 434.65183 | Q36: =0.168*($G2)*(1+$B$9)^(Table6[[#Headers],[15]]-1) -> 443.34486 | R36: =0.168*($G2)*(1+$B$9)^(Table6[[#Headers],[16]]-1) -> 452.21176 | S36: =0.168*($G2)*(1+$B$9)^(Table6[[#Headers],[17]]-1) -> 461.256 | T36: =0.168*($G2)*(1+$B$9)^(Table6[[#Headers],[18]]-1) -> 470.48112 | U36: =0.168*($G2)*(1+$B$9)^(Table6[[#Headers],[19]]-1) -> 479.89074 | V36: =0.168*($G2)*(1+$B$9)^(Table6[[#Headers],[20]]-1)+F2 -> 543.48855
A37: Mixed Mode | B37: 0 | C37: =0.168*($G3)*(1+$B$9)^(Table6[[#Headers],[1]]-1) -> 336 | D37: =0.168*($G3)*(1+$B$9)^(Table6[[#Headers],[2]]-1) -> 342.72 | E37: =0.168*($G3)*(1+$B$9)^(Table6[[#Headers],[3]]-1) -> 349.5744 | F37: =0.168*($G3)*(1+$B$9)^(Table6[[#Headers],[4]]-1) -> 356.56589 | G37: =0.168*($G3)*(1+$B$9)^(Table6[[#Headers],[5]]-1) -> 363.69721 | H37: =0.168*($G3)*(1+$B$9)^(Table6[[#Headers],[6]]-1) -> 370.97115 | I37: =0.168*($G3)*(1+$B$9)^(Table6[[#Headers],[7]]-1) -> 378.39057 | J37: =0.168*($G3)*(1+$B$9)^(Table6[[#Headers],[8]]-1) -> 385.95838 | K37: =0.168*($G3)*(1+$B$9)^(Table6[[#Headers],[9]]-1) -> 393.67755 | L37: =0.168*($G3)*(1+$B$9)^(Table6[[#Headers],[10]]-1) -> 401.5511 | M37: =0.168*($G3)*(1+$B$9)^(Table6[[#Headers],[11]]-1) -> 409.58213 | N37: =0.168*($G3)*(1+$B$9)^(Table6[[#Headers],[12]]-1) -> 417.77377 | O37: =0.168*($G3)*(1+$B$9)^(Table6[[#Headers],[13]]-1) -> 426.12924 | P37: =0.168*($G3)*(1+$B$9)^(Table6[[#Headers],[14]]-1) -> 434.65183 | Q37: =0.168*($G3)*(1+$B$9)^(Table6[[#Headers],[15]]-1) -> 443.34486 | R37: =0.168*($G3)*(1+$B$9)^(Table6[[#Headers],[16]]-1) -> 452.21176 | S37: =0.168*($G3)*(1+$B$9)^(Table6[[#Headers],[17]]-1) -> 461.256 | T37: =0.168*($G3)*(1+$B$9)^(Table6[[#Headers],[18]]-1) -> 470.48112 | U37: =0.168*($G3)*(1+$B$9)^(Table6[[#Headers],[19]]-1) -> 479.89074 | V37: =0.168*($G3)*(1+$B$9)^(Table6[[#Headers],[20]]-1)+F3 -> 539.48855
A39: Costs without interest rate: ($)
A40: System | B40: 0 | C40: 1 | D40: 2 | E40: 3 | F40: 4 | G40: 5 | H40: 6 | I40: 7 | J40: 8 | K40: 9 | L40: 10 | M40: 11 | N40: 12 | O40: 13 | P40: 14 | Q40: 15 | R40: 16 | S40: 17 | T40: 18 | U40: 19 | V40: 20
A41: CCDV | B41: =B16 -> -2100 | C41: =0.168*(-$D2)*(1+$B$9)^(Table6[[#Headers],[1]]-1)-$E2 -> -151.12 | D41: =0.168*(-$D2)*(1+$B$9)^(Table6[[#Headers],[2]]-1)-$E2 -> -153.9424 | E41: =0.168*(-$D2)*(1+$B$9)^(Table6[[#Headers],[3]]-1)-$E2 -> -156.82125 | F41: =0.168*(-$D2)*(1+$B$9)^(Table6[[#Headers],[4]]-1)-$E2 -> -159.75767 | G41: =0.168*(-$D2)*(1+$B$9)^(Table6[[#Headers],[5]]-1)-$E2 -> -162.75283 | H41: =0.168*(-$D2)*(1+$B$9)^(Table6[[#Headers],[6]]-1)-$E2 -> -165.80788 | I41: =0.168*(-$D2)*(1+$B$9)^(Table6[[#Headers],[7]]-1)-$E2 -> -168.92404 | J41: =0.168*(-$D2)*(1+$B$9)^(Table6[[#Headers],[8]]-1)-$E2 -> -172.10252 | K41: =0.168*(-$D2)*(1+$B$9)^(Table6[[#Headers],[9]]-1)-$E2 -> -175.34457 | L41: =0.168*(-$D2)*(1+$B$9)^(Table6[[#Headers],[10]]-1)-$E2 -> -178.65146 | M41: =0.168*(-$D2)*(1+$B$9)^(Table6[[#Headers],[11]]-1)-$E2 -> -182.02449 | N41: =0.168*(-$D2)*(1+$B$9)^(Table6[[#Headers],[12]]-1)-$E2 -> -185.46498 | O41: =0.168*(-$D2)*(1+$B$9)^(Table6[[#Headers],[13]]-1)-$E2 -> -188.97428 | P41: =0.168*(-$D2)*(1+$B$9)^(Table6[[#Headers],[14]]-1)-$E2 -> -192.55377 | Q41: =0.168*(-$D2)*(1+$B$9)^(Table6[[#Headers],[15]]-1)-$E2 -> -196.20484 | R41: =0.168*(-$D2)*(1+$B$9)^(Table6[[#Headers],[16]]-1)-$E2 -> -199.92894 | S41: =0.168*(-$D2)*(1+$B$9)^(Table6[[#Headers],[17]]-1)-$E2 -> -203.72752 | T41: =0.168*(-$D2)*(1+$B$9)^(Table6[[#Headers],[18]]-1)-$E2 -> -207.60207 | U41: =0.168*(-$D2)*(1+$B$9)^(Table6[[#Headers],[19]]-1)-$E2 -> -211.55411 | V41: =0.168*(-$D2)*(1+$B$9)^(Table6[[#Headers],[20]]-1)-$E2 -> -215.58519
A42: Mixed Mode | B42: =B17 -> -1134 | C42: =0.168*(-$D3)*(1+$B$9)^(Table6[[#Headers],[1]]-1)-$E3 -> -262.8 | D42: =0.168*(-$D3)*(1+$B$9)^(Table6[[#Headers],[2]]-1)-$E3 -> -267.84 | E42: =0.168*(-$D3)*(1+$B$9)^(Table6[[#Headers],[3]]-1)-$E3 -> -272.9808 | F42: =0.168*(-$D3)*(1+$B$9)^(Table6[[#Headers],[4]]-1)-$E3 -> -278.22442 | G42: =0.168*(-$D3)*(1+$B$9)^(Table6[[#Headers],[5]]-1)-$E3 -> -283.5729 | H42: =0.168*(-$D3)*(1+$B$9)^(Table6[[#Headers],[6]]-1)-$E3 -> -289.02836 | I42: =0.168*(-$D3)*(1+$B$9)^(Table6[[#Headers],[7]]-1)-$E3 -> -294.59293 | J42: =0.168*(-$D3)*(1+$B$9)^(Table6[[#Headers],[8]]-1)-$E3 -> -300.26879 | K42: =0.168*(-$D3)*(1+$B$9)^(Table6[[#Headers],[9]]-1)-$E3 -> -306.05816 | L42: =0.168*(-$D3)*(1+$B$9)^(Table6[[#Headers],[10]]-1)-$E3 -> -311.96333 | M42: =0.168*(-$D3)*(1+$B$9)^(Table6[[#Headers],[11]]-1)-$E3 -> -317.98659 | N42: =0.168*(-$D3)*(1+$B$9)^(Table6[[#Headers],[12]]-1)-$E3 -> -324.13033 | O42: =0.168*(-$D3)*(1+$B$9)^(Table6[[#Headers],[13]]-1)-$E3 -> -330.39693 | P42: =0.168*(-$D3)*(1+$B$9)^(Table6[[#Headers],[14]]-1)-$E3 -> -336.78887 | Q42: =0.168*(-$D3)*(1+$B$9)^(Table6[[#Headers],[15]]-1)-$E3 -> -343.30865 | R42: =0.168*(-$D3)*(1+$B$9)^(Table6[[#Headers],[16]]-1)-$E3 -> -349.95882 | S42: =0.168*(-$D3)*(1+$B$9)^(Table6[[#Headers],[17]]-1)-$E3 -> -356.742 | T42: =0.168*(-$D3)*(1+$B$9)^(Table6[[#Headers],[18]]-1)-$E3 -> -363.66084 | U42: =0.168*(-$D3)*(1+$B$9)^(Table6[[#Headers],[19]]-1)-$E3 -> -370.71805 | V42: =0.168*(-$D3)*(1+$B$9)^(Table6[[#Headers],[20]]-1)-$E3 -> -377.91642
A44: Benefits with Interest rate: ($)
A45: System | B45: 0 | C45: 1 | D45: 2 | E45: 3 | F45: 4 | G45: 5 | H45: 6 | I45: 7 | J45: 8 | K45: 9 | L45: 10 | M45: 11 | N45: 12 | O45: 13 | P45: 14 | Q45: 15 | R45: 16 | S45: 17 | T45: 18 | U45: 19 | V45: 20
A46: CCDV | B46: =B36/(1+$B$12)^B45 -> 0 | C46: =C36/(1+$B$12)^C45 -> 332.95274 | D46: =D36/(1+$B$12)^D45 -> 336.53179 | E46: =E36/(1+$B$12)^E45 -> 340.1493 | F46: =F36/(1+$B$12)^F45 -> 343.80571 | G46: =G36/(1+$B$12)^G45 -> 347.50141 | H46: =H36/(1+$B$12)^H45 -> 351.23685 | I46: =I36/(1+$B$12)^I45 -> 355.01243 | ... V46: =V36/(1+$B$12)^V45 -> 452.95686
A47: Mixed Mode | B47: =B37/(1+$B$12)^B46 -> 0 | C47: =C37/(1+$B$12)^C45 -> 332.95274 | D47: =D37/(1+$B$12)^D45 -> 336.53179 | E47: =E37/(1+$B$12)^E45 -> 340.1493 | F47: =F37/(1+$B$12)^F45 -> 343.80571 | G47: =G37/(1+$B$12)^G45 -> 347.50141 | H47: =H37/(1+$B$12)^H45 -> 351.23685 | I47: =I37/(1+$B$12)^I45 -> 355.01243 | J47: =J37/(1+$B$12)^J45 -> 358.8286 | ... V47: =V37/(1+$B$12)^V45 -> 449.62316
A50: Costs with interest rate: ($)
A51: System | B51: 0 | C51: 1 | D51: 2 | E51: 3 | F51: 4 | G51: 5 | H51: 6 | I51: 7 | J51: 8 | K51: 9 | L51: 10 | M51: 11 | N51: 12 | O51: 13 | P51: 14 | Q51: 15 | R51: 16 | S51: 17 | T51: 18 | U51: 19 | V51: 20
A52: CCDV | B52: =B41/(1+$B$12)^B51 -> -2100 | C52: =C41/(1+$B$12)^C51 -> -149.74946 | D52: =D41/(1+$B$12)^D51 -> -151.16279 | E52: =E41/(1+$B$12)^E51 -> -152.59309 | F52: =F41/(1+$B$12)^F51 -> -154.04053 | G52: =G41/(1+$B$12)^G51 -> -155.50528 | H52: =H41/(1+$B$12)^H51 -> -156.98751 | I52: =I41/(1+$B$12)^I51 -> -158.48739 | ... V52: =V41/(1+$B$12)^V51 -> -179.67405
A53: Mixed Mode | B53: =B42/(1+$B$12)^B51 -> -1134 | C53: =C42/(1+$B$12)^C51 -> -260.41661 | D53: =D42/(1+$B$12)^D51 -> -263.00383 | E53: =E42/(1+$B$12)^E51 -> -265.62079 | F53: =F42/(1+$B$12)^F51 -> -268.26779 | G53: =G42/(1+$B$12)^G51 -> -270.94512 | H53: =H42/(1+$B$12)^H51 -> -273.65311 | I53: =I42/(1+$B$12)^I51 -> -276.39207 | ... V53: =V42/(1+$B$12)^V51 -> -314.96493
A57: System | B57: NPV Benefit | C57: NPV Costs | D57: B/C Ratio
A58: CCDV | B58: =SUM(B46:V46) -> 7430.0113 | C58: =SUM(B52:V52) -> -5383.708 | D58: =B58/-C58 -> 1.3800918
A59: Mixed Mode | B59: =SUM(B47:V47) -> 7426.6776 | C59: =SUM(B53:V53) -> -6869.3205 | D59: =B59/-C59 -> 1.0811372
A62: System | B62: Initial Invest+Installation | C62: Annual cost($) | D62: Annual Energy(KWh)
A63: Full Diesel | B63: 0 | C63: 1500*electricity cost | D63: 1500
A64: Half Diesel Half PV | B64: 1000 | C64: 840*electricity cost | D64: 1680
...

Sheet to post
A12: Costs without interest rate:($)
A13: System | B13: 0 | C13: 1 | D13: 2 | E13: 3 | F13: 4 | G13: 5 | H13: 6 | I13: 7 | J13: 8 | K13: 9 | L13: 10 | M13: 11 | N13: 12 | O13: 13 | P13: 14 | Q13: 15 | R13: 16 | S13: 17 | T13: 18 | U13: 19 | V13: 20
A14: CCDV | B14: -2100 | C14: 184.88 | D14: 188.7776 | E14: 192.75315 | F14: 196.80822 | G14: 200.94438 | H14: 205.16327 | I14: 209.46653 | J14: 213.85586 | K14: 218.33298 | L14: 222.89964 | M14: 227.55763 | N14: 232.30879 | O14: 237.15496 | P14: 242.09806 | Q14: 247.14002 | R14: 252.28282 | S14: 257.52848 | T14: 262.87905 | U14: 268.33663 | V14: 327.90336
A15: Mixed Mode | B15: -1134 | C15: 73.2 | D15: 74.88 | E15: 76.5936 | F15: 78.341472 | G15: 80.124301 | H15: 81.942787 | I15: 83.797643 | J15: 85.689596 | K15: 87.619388 | L15: 89.587776 | M15: 91.595531 | N15: 93.643442 | O15: 95.732311 | P15: 97.862957 | Q15: 100.03622 | R15: 102.25294 | S15: 104.514 | T15: 106.82028 | U15: 109.17268 | V15: 161.57214
A19: Costs with intest rate:($)
A20: System | B20: 0 | C20: 1 | D20: 2 | E20: 3 | F20: 4 | G20: 5 | H20: 6 | I20: 7 | J20: 8 | K20: 9 | L20: 10 | M20: 11 | N20: 12 | O20: 13 | P20: 14 | Q20: 15 | R20: 16 | S20: 17 | T20: 18 | U20: 19 | V20: 20
A21: CCDV | B21: -2100 | C21: 183.20328 | D21: 185.369 | E21: 187.55621 | F21: 189.76517 | G21: 191.99613 | H21: 194.24933 | I21: 196.52504 | J21: 198.82351 | K21: 201.145 | L21: 203.48977 | M21: 205.85809 | N21: 208.25023 | O21: 210.66646 | P21: 213.10705 | Q21: 215.57228 | R21: 218.06242 | S21: 220.57777 | T21: 223.1186 | U21: 225.6852 | V21: 273.2828
A22: Mixed Mode | B22: -1134 | C22: 72.536134 | D22: 73.527954 | E22: 74.528512 | F22: 75.537919 | G22: 76.556288 | H22: 77.583732 | I22: 78.620365 | J22: 79.666304 | K22: 80.721665 | L22: 81.786566 | M22: 82.861125 | N22: 83.945463 | O22: 85.039701 | P22: 86.143962 | Q22: 87.258368 | R22: 88.383044 | S22: 89.518117 | T22: 90.663713 | U22: 91.819961 | V22: 134.65823
A28: Benefits without interest rate: ($)
A29: System | B29: 0 | C29: 1 | D29: 2 | E29: 3 | F29: 4 | G29: 5 | H29: 6 | I29: 7 | J29: 8 | K29: 9 | L29: 10 | M29: 11 | N29: 12 | O29: 13 | P29: 14 | Q29: 15 | R29: 16 | S29: 17 | T29: 18 | U29: 19 | V29: 20
A30: CCDV | B30: 0 | C30: 336 | D30: 342.72 | E30: 349.5744 | F30: 356.56589 | G30: 363.69721 | H30: 370.97115 | I30: 378.39057 | J30: 385.95838 | K30: 393.67755 | L30: 401.5511 | M30: 409.58213 | N30: 417.77377 | O30: 426.12924 | P30: 434.65183 | Q30: 443.34486 | R30: 452.21176 | S30: 461.256 | T30: 470.48112 | U30: 479.89074 | V30: 543.48855
A31: Mixed Mode | B31: 0 | C31: 336 | D31: 342.72 | E31: 349.5744 | F31: 356.56589 | G31: 363.69721 | H31: 370.97115 | I31: 378.39057 | J31: 385.95838 | K31: 393.67755 | L31: 401.5511 | M31: 409.58213 | N31: 417.77377 | O31: 426.12924 | P31: 434.65183 | Q31: 443.34486 | R31: 452.21176 | S31: 461.256 | T31: 470.48112 | U31: 479.89074 | V31: 539.48855
A34: Costs without interest rate: ($)
A35: System | B35: 0 | C35: 1 | D35: 2 | E35: 3 | F35: 4 | G35: 5 | H35: 6 | I35: 7 | J35: 8 | K35: 9 | L35: 10 | M35: 11 | N35: 12 | O35: 13 | P35: 14 | Q35: 15 | R35: 16 | S35: 17 | T35: 18 | U35: 19 | V35: 20
A36: CCDV | B36: -2100 | C36: -151.12 | D36: -153.9424 | E36: -156.82125 | F36: -159.75767 | G36: -162.75283 | H36: -165.80788 | I36: -168.92404 | J36: -172.10252 | K36: -175.34457 | L36: -178.65146 | M36: -182.02449 | N36: -185.46498 | O36: -188.97428 | P36: -192.55377 | Q36: -196.20484 | R36: -199.92894 | S36: -203.72752 | T36: -207.60207 | U36: -211.55411 | V36: -215.58519
A37: Mixed Mode | B37: -1134 | C37: -262.8 | D37: -267.84 | E37: -272.9808 | F37: -278.22442 | G37: -283.5729 | H37: -289.02836 | I37: -294.59293 | J37: -300.26879 | K37: -306.05816 | L37: -311.96333 | M37: -317.98659 | N37: -324.13033 | O37: -330.39693 | P37: -336.78887 | Q37: -343.30865 | R37: -349.95882 | S37: -356.742 | T37: -363.66084 | U37: -370.71805 | V37: -377.91642
A40: Benefits with Interest rate: ($)
A41: System | B41: 0 | C41: 1 | D41: 2 | E41: 3 | F41: 4 | G41: 5 | H41: 6 | I41: 7 | J41: 8 | K41: 9 | L41: 10 | M41: 11 | N41: 12 | O41: 13 | P41: 14 | Q41: 15 | R41: 16 | S41: 17 | T41: 18 | U41: 19 | V41: 20
A42: CCDV | B42: 0 | C42: 332.95274 | D42: 336.53179 | E42: 340.1493 | F42: 343.80571 | G42: 347.50141 | H42: 351.23685 | I42: 355.01243 | J42: 358.8286 | K42: 362.6858 | L42: 366.58445 | M42: 370.52502 | N42: 374.50794 | O42: 378.53368 | P42: 382.60269 | Q42: 386.71544 | R42: 390.8724 | S42: 395.07404 | T42: 399.32085 | U42: 403.61331 | V42: 452.95686
A43: Mixed Mode | B43: 0 | C43: 332.95274 | D43: 336.53179 | E43: 340.1493 | F43: 343.80571 | G43: 347.50141 | H43: 351.23685 | I43: 355.01243 | J43: 358.8286 | K43: 362.6858 | L43: 366.58445 | M43: 370.52502 | N43: 374.50794 | O43: 378.53368 | P43: 382.60269 | Q43: 386.71544 | R43: 390.8724 | S43: 395.07404 | T43: 399.32085 | U43: 403.61331 | V43: 449.62316
A45: Costs with interest rate: ($)
A46: System | B46: 0 | C46: 1 | D46: 2 | E46: 3 | F46: 4 | G46: 5 | H46: 6 | I46: 7 | J46: 8 | K46: 9 | L46: 10 | M46: 11 | N46: 12 | O46: 13 | P46: 14 | Q46: 15 | R46: 16 | S46: 17 | T46: 18 | U46: 19 | V46: 20
A47: CCDV | B47: -2100 | C47: -149.74946 | D47: -151.16279 | E47: -152.59309 | F47: -154.04053 | G47: -155.50528 | H47: -156.98751 | I47: -158.48739 | J47: -160.00509 | K47: -161.5408 | L47: -163.09468 | M47: -164.66692 | N47: -166.25771 | O47: -167.86722 | P47: -169.49564 | Q47: -171.14316 | R47: -172.80998 | S47: -174.49628 | T47: -176.20226 | U47: -177.92812 | V47: -179.67405
A48: Mixed Mode | B48: -1134 | C48: -260.41661 | D48: -263.00383 | E48: -265.62079 | F48: -268.26779 | G48: -270.94512 | H48: -273.65311 | I48: -276.39207 | J48: -279.1623 | K48: -281.96413 | L48: -284.79789 | M48: -287.66389 | N48: -290.56248 | O48: -293.49398 | P48: -296.45873 | Q48: -299.45707 | R48: -302.48935 | S48: -305.55593 | T48: -308.65714 | U48: -311.79335 | V48: -314.96493
A62: Cashflow costs for energy
A63: System | B63: 0 | C63: 1 | D63: 2 | E63: 3 | F63: 4 | G63: 5 | H63: 6 | I63: 7 | J63: 8 | K63: 9 | L63: 10 | M63: 11 | N63: 12 | O63: 13 | P63: 14 | Q63: 15 | R63: 16 | S63: 17 | T63: 18 | U63: 19 | V63: 20
A64: Full Diesel | B64: 0 | C64: =0.168*(1500)*(1+$B$9)^(Table6[[#Headers],[1]]-1) -> 252 | D64: =0.168*(1500)*(1+$B$9)^(Table6[[#Headers],[2]]-1) -> 252 | E64: =0.168*(1500)*(1+$B$9)^(Table6[[#Headers],[3]]-1) -> 252 | F64: =0.168*(1500)*(1+$B$9)^(Table6[[#Headers],[4]]-1) -> 252 | G64: =0.168*(1500)*(1+$B$9)^(Table6[[#Headers],[5]]-1) -> 252 | H64: =0.168*(1500)*(1+$B$9)^(Table6[[#Headers],[6]]-1) -> 252 | I64: =0.168*(1500)*(1+$B$9)^(Table6[[#Headers],[7]]-1) -> 252 | J64: =0.168*(1500)*(1+$B$9)^(Table6[[#Headers],[8]]-1) -> 252 | K64: =0.168*(1500)*(1+$B$9)^(Table6[[#Headers],[9]]-1) -> 252 | L64: =0.168*(1500)*(1+$B$9)^(Table6[[#Headers],[10]]-1) -> 252 | M64: =0.168*(1500)*(1+$B$9)^(Table6[[#Headers],[11]]-1) -> 252 | N64: =0.168*(1500)*(1+$B$9)^(Table6[[#Headers],[12]]-1) -> 252 | O64: =0.168*(1500)*(1+$B$9)^(Table6[[#Headers],[13]]-1) -> 252 | P64: =0.168*(1500)*(1+$B$9)^(Table6[[#Headers],[14]]-1) -> 252 | Q64: =0.168*(1500)*(1+$B$9)^(Table6[[#Headers],[15]]-1) -> 252 | R64: =0.168*(1500)*(1+$B$9)^(Table6[[#Headers],[16]]-1) -> 252 | S64: =0.168*(1500)*(1+$B$9)^(Table6[[#Headers],[17]]-1) -> 252 | T64: =0.168*(1500)*(1+$B$9)^(Table6[[#Headers],[18]]-1) -> 252 | U64: =0.168*(1500)*(1+$B$9)^(Table6[[#Headers],[19]]-1) -> 252 | V64: =0.168*(1500)*(1+$B$9)^(Table6[[#Headers],[20]]-1) -> 252
A65: Half Diesel Half PV | B65: 1000 | C65: =0.168*(840)*(1+$B$9)^(Table6[[#Headers],[1]]-1) -> 141.12 | D65: =0.168*(840)*(1+$B$9)^(Table6[[#Headers],[2]]-1) -> 141.12 | E65: =0.168*(840)*(1+$B$9)^(Table6[[#Headers],[3]]-1) -> 141.12 | F65: =0.168*(840)*(1+$B$9)^(Table6[[#Headers],[4]]-1) -> 141.12 | G65: =0.168*(840)*(1+$B$9)^(Table6[[#Headers],[5]]-1) -> 141.12 | H65: =0.168*(840)*(1+$B$9)^(Table6[[#Headers],[6]]-1) -> 141.12 | I65: =0.168*(840)*(1+$B$9)^(Table6[[#Headers],[7]]-1) -> 141.12 | J65: =0.168*(840)*(1+$B$9)^(Table6[[#Headers],[8]]-1) -> 141.12 | K65: =0.168*(840)*(1+$B$9)^(Table6[[#Headers],[9]]-1) -> 141.12 | L65: =0.168*(840)*(1+$B$9)^(Table6[[#Headers],[10]]-1) -> 141.12 | M65: =0.168*(840)*(1+$B$9)^(Table6[[#Headers],[11]]-1) -> 141.12 | N65: =0.168*(840)*(1+$B$9)^(Table6[[#Headers],[12]]-1) -> 141.12 | O65: =0.168*(840)*(1+$B$9)^(Table6[[#Headers],[13]]-1) -> 141.12 | P65: =0.168*(840)*(1+$B$9)^(Table6[[#Headers],[14]]-1) -> 141.12 | Q65: =0.168*(840)*(1+$B$9)^(Table6[[#Headers],[15]]-1) -> 141.12 | R65: =0.168*(840)*(1+$B$9)^(Table6[[#Headers],[16]]-1) -> 141.12 | S65: =0.168*(840)*(1+$B$9)^(Table6[[#Headers],[17]]-1) -> 141.12 | T65: =0.168*(840)*(1+$B$9)^(Table6[[#Headers],[18]]-1) -> 141.12 | U65: =0.168*(840)*(1+$B$9)^(Table6[[#Headers],[19]]-1) -> 141.12 | V65: =0.168*(840)*(1+$B$9)^(Table6[[#Headers],[20]]-1) -> 141.12
A70: NPV costs for energy
A71: System | B71: 0 | C71: 1 | D71: 2 | E71: 3 | F71: 4 | G71: 5 | H71: 6 | I71: 7 | J71: 8 | K71: 9 | L71: 10 | M71: 11 | N71: 12 | O71: 13 | P71: 14 | Q71: 15 | R71: 16 | S71: 17 | T71: 18 | U71: 19 | V71: 20
A72: Full Diesel | B72: 0 | C72: 249.71456 | D72: 252.39884 | E72: 255.11198 | F72: 257.85428 | G72: 260.62606 | H72: 263.42763 | I72: 266.25932 | J72: 269.12145 | K72: 272.01435 | L72: 274.93834 | M72: 277.89376 | N72: 280.88095 | O72: 283.90026 | P72: 286.95202 | Q72: 290.03658 | R72: 293.1543 | S72: 296.30553 | T72: 299.49064 | U72: 302.70999 | V72: 305.96394
A73: Half Diesel Half PV | B73: 1000 | C73: 139.84015 | D73: 141.34335 | E73: 142.86271 | F73: 144.3984 | G73: 145.95059 | H73: 147.51947 | I73: 149.10522 | J73: 150.70801 | K73: 152.32803 | L73: 153.96547 | M73: 155.62051 | N73: 157.29333 | O73: 158.98414 | P73: 160.69313 | Q73: 162.42048 | R73: 164.16641 | S73: 165.9311 | T73: 167.71476 | U73: 169.51759 | V73: 171.33981
A78: Energy with interest
A79: System | B79: 0 | C79: 1 | D79: 2 | E79: 3 | F79: 4 | G79: 5 | H79: 6 | I79: 7 | J79: 8 | K79: 9 | L79: 10 | M79: 11 | N79: 12 | O79: 13 | P79: 14 | Q79: 15 | R79: 16 | S79: 17 | T79: 18 | U79: 19 | V79: 20
A80: Full Diesel | B80: 0 | C80: 1486.3962 | D80: 1472.9157 | E80: 1459.5576 | F80: 1446.3205 | G80: 1433.2035 | H80: 1420.2055 | I80: 1407.3254 | J80: 1394.562 | K80: 1381.9144 | L80: 1369.3816 | M80: 1356.9624 | N80: 1344.6558 | O80: 1332.4608 | P80: 1320.3764 | Q80: 1308.4017 | R80: 1296.5355 | S80: 1284.7769 | T80: 1273.125 | U80: 1261.5788 | V80: 1250.1373
A81: Half Diesel Half PV | B81: 0 | C81: 1664.7637 | D81: 1649.6656 | E81: 1634.7045 | F81: 1619.879 | G81: 1605.188 | H81: 1590.6302 | I81: 1576.2044 | J81: 1561.9095 | K81: 1547.7442 | L81: 1533.7074 | M81: 1519.7978 | N81: 1506.0145 | O81: 1492.3561 | P81: 1478.8216 | Q81: 1465.4099 | R81: 1452.1197 | S81: 1438.9502 | T81: 1425.9 | U81: 1412.9682 | V81: 1400.1537
